Workbook
Name Dia_A: 'Rentabilidad x Cedi'!$G$9
Name EERR_Año: '[1]BD Llenado'!$U$6:$U$20102

Sheet analisis segmento
A1: Region | B1: Territorio | C1: Cedis | D1: Ruta | E1: Mix de categoría por región (target Conservador) | F1: % utilización OP (Venta CU) | G1: % utilización GFN (Venta CU) | H1: OP incremental (CU/día) | I1: GFN incremental (CU/día)
A2: =IF('[3]Motor Rutas SKU_Cons'!C6="","",'[3]Motor Rutas SKU_Cons'!C6) -> Norte | B2: =IF('[3]Motor Rutas SKU_Cons'!D6="","",'[3]Motor Rutas SKU_Cons'!D6) -> Comarca | C2: =IF('[3]Motor Rutas SKU_Cons'!B6="","",'[3]Motor Rutas SKU_Cons'!B6) -> Suc. San Pedro | D2: ='[3]Motor Rutas SKU_Cons'!A6 -> 219340 | E2: =IF('[3]Motor Rutas SKU_Cons'!N6="","s/d","Agua "&TEXT('[3]Motor Rutas SKU_Cons'!N6,"0%")&" · Colas "&TEXT('[3]Motor Rutas SKU_Cons'!O6,"0%")&" · Resto "&TEXT('[3]Motor Rutas SKU_Cons'!P6,"0%")) -> Agua 85% · Colas 8% · Resto 7% | F2: ='[3]Motor Rutas SKU_Cons'!CH6 -> 0.16100098 | G2: ='[3]Motor Rutas SKU_Cons'!CG6 -> 0.49329849 | H2: ='[3]Motor Rutas SKU_Cons'!BX6 -> 0 | I2: ='[3]Motor Rutas SKU_Cons'!BW6 -> 0
A3: =IF('[3]Motor Rutas SKU_Cons'!C7="","",'[3]Motor Rutas SKU_Cons'!C7) -> Norte | B3: =IF('[3]Motor Rutas SKU_Cons'!D7="","",'[3]Motor Rutas SKU_Cons'!D7) -> Juárez | C3: =IF('[3]Motor Rutas SKU_Cons'!B7="","",'[3]Motor Rutas SKU_Cons'!B7) -> Suc. Casas Grandes | D3: ='[3]Motor Rutas SKU_Cons'!A7 -> 305400 | E3: =IF('[3]Motor Rutas SKU_Cons'!N7="","s/d","Agua "&TEXT('[3]Motor Rutas SKU_Cons'!N7,"0%")&" · Colas "&TEXT('[3]Motor Rutas SKU_Cons'!O7,"0%")&" · Resto "&TEXT('[3]Motor Rutas SKU_Cons'!P7,"0%")) -> Agua 85% · Colas 8% · Resto 7% | F3: ='[3]Motor Rutas SKU_Cons'!CH7 -> 0.10448758 | G3: ='[3]Motor Rutas SKU_Cons'!CG7 -> 0.48448109 | H3: ='[3]Motor Rutas SKU_Cons'!BX7 -> 0 | I3: ='[3]Motor Rutas SKU_Cons'!BW7 -> 0
A4: =IF('[3]Motor Rutas SKU_Cons'!C8="","",'[3]Motor Rutas SKU_Cons'!C8) -> Sin región | B4: =IF('[3]Motor Rutas SKU_Cons'!D8="","",'[3]Motor Rutas SKU_Cons'!D8) -> Sin territorio | C4: =IF('[3]Motor Rutas SKU_Cons'!B8="","",'[3]Motor Rutas SKU_Cons'!B8) -> Sin CeDi | D4: ='[3]Motor Rutas SKU_Cons'!A8 -> 309399 | E4: =IF('[3]Motor Rutas SKU_Cons'!N8="","s/d","Agua "&TEXT('[3]Motor Rutas SKU_Cons'!N8,"0%")&" · Colas "&TEXT('[3]Motor Rutas SKU_Cons'!O8,"0%")&" · Resto "&TEXT('[3]Motor Rutas SKU_Cons'!P8,"0%")) -> s/d | F4: ='[3]Motor Rutas SKU_Cons'!CH8 | G4: ='[3]Motor Rutas SKU_Cons'!CG8 | H4: ='[3]Motor Rutas SKU_Cons'!BX8 -> 0 | I4: ='[3]Motor Rutas SKU_Cons'!BW8 -> 0
A5: =IF('[3]Motor Rutas SKU_Cons'!C9="","",'[3]Motor Rutas SKU_Cons'!C9) -> Sin región | B5: =IF('[3]Motor Rutas SKU_Cons'!D9="","",'[3]Motor Rutas SKU_Cons'!D9) -> Sin territorio | C5: =IF('[3]Motor Rutas SKU_Cons'!B9="","",'[3]Motor Rutas SKU_Cons'!B9) -> Sin CeDi | D5: ='[3]Motor Rutas SKU_Cons'!A9 -> 312399 | E5: =IF('[3]Motor Rutas SKU_Cons'!N9="","s/d","Agua "&TEXT('[3]Motor Rutas SKU_Cons'!N9,"0%")&" · Colas "&TEXT('[3]Motor Rutas SKU_Cons'!O9,"0%")&" · Resto "&TEXT('[3]Motor Rutas SKU_Cons'!P9,"0%")) -> s/d | F5: ='[3]Motor Rutas SKU_Cons'!CH9 | G5: ='[3]Motor Rutas SKU_Cons'!CG9 | H5: ='[3]Motor Rutas SKU_Cons'!BX9 -> 0 | I5: ='[3]Motor Rutas SKU_Cons'!BW9 -> 0
A6: =IF('[3]Motor Rutas SKU_Cons'!C10="","",'[3]Motor Rutas SKU_Cons'!C10) -> Pacifico | B6: =IF('[3]Motor Rutas SKU_Cons'!D10="","",'[3]Motor Rutas SKU_Cons'!D10) -> Hermosillo | C6: =IF('[3]Motor Rutas SKU_Cons'!B10="","",'[3]Motor Rutas SKU_Cons'!B10) -> Planta Hermosillo | D6: ='[3]Motor Rutas SKU_Cons'!A10 -> 401300 | E6: =IF('[3]Motor Rutas SKU_Cons'!N10="","s/d","Agua "&TEXT('[3]Motor Rutas SKU_Cons'!N10,"0%")&" · Colas "&TEXT('[3]Motor Rutas SKU_Cons'!O10,"0%")&" · Resto "&TEXT('[3]Motor Rutas SKU_Cons'!P10,"0%")) -> Agua 85% · Colas 8% · Resto 7% | F6: ='[3]Motor Rutas SKU_Cons'!CH10 -> 0.20658303 | G6: ='[3]Motor Rutas SKU_Cons'!CG10 | H6: ='[3]Motor Rutas SKU_Cons'!BX10 -> 0 | I6: ='[3]Motor Rutas SKU_Cons'!BW10 -> 0
A7: =IF('[3]Motor Rutas SKU_Cons'!C11="","",'[3]Motor Rutas SKU_Cons'!C11) -> Pacifico | B7: =IF('[3]Motor Rutas SKU_Cons'!D11="","",'[3]Motor Rutas SKU_Cons'!D11) -> Hermosillo | C7: =IF('[3]Motor Rutas SKU_Cons'!B11="","",'[3]Motor Rutas SKU_Cons'!B11) -> Planta Hermosillo | D7: ='[3]Motor Rutas SKU_Cons'!A11 -> 401301 | E7: =IF('[3]Motor Rutas SKU_Cons'!N11="","s/d","Agua "&TEXT('[3]Motor Rutas SKU_Cons'!N11,"0%")&" · Colas "&TEXT('[3]Motor Rutas SKU_Cons'!O11,"0%")&" · Resto "&TEXT('[3]Motor Rutas SKU_Cons'!P11,"0%")) -> Agua 85% · Colas 8% · Resto 7% | F7: ='[3]Motor Rutas SKU_Cons'!CH11 -> 0.073576436 | G7: ='[3]Motor Rutas SKU_Cons'!CG11 | H7: ='[3]Motor Rutas SKU_Cons'!BX11 -> 0 | I7: ='[3]Motor Rutas SKU_Cons'!BW11 -> 0
A8: =IF('[3]Motor Rutas SKU_Cons'!C12="","",'[3]Motor Rutas SKU_Cons'!C12) -> Pacifico | B8: =IF('[3]Motor Rutas SKU_Cons'!D12="","",'[3]Motor Rutas SKU_Cons'!D12) -> Hermosillo | C8: =IF('[3]Motor Rutas SKU_Cons'!B12="","",'[3]Motor Rutas SKU_Cons'!B12) -> Planta Hermosillo | D8: ='[3]Motor Rutas SKU_Cons'!A12 -> 401302 | E8: =IF('[3]Motor Rutas SKU_Cons'!N12="","s/d","Agua "&TEXT('[3]Motor Rutas SKU_Cons'!N12,"0%")&" · Colas "&TEXT('[3]Motor Rutas SKU_Cons'!O12,"0%")&" · Resto "&TEXT('[3]Motor Rutas SKU_Cons'!P12,"0%")) -> Agua 85% · Colas 8% · Resto 7% | F8: ='[3]Motor Rutas SKU_Cons'!CH12 -> 0.14911054 | G8: ='[3]Motor Rutas SKU_Cons'!CG12 | H8: ='[3]Motor Rutas SKU_Cons'!BX12 -> 0 | I8: ='[3]Motor Rutas SKU_Cons'!BW12 -> 0
A9: =IF('[3]Motor Rutas SKU_Cons'!C13="","",'[3]Motor Rutas SKU_Cons'!C13) -> Pacifico | B9: =IF('[3]Motor Rutas SKU_Cons'!D13="","",'[3]Motor Rutas SKU_Cons'!D13) -> Hermosillo | C9: =IF('[3]Motor Rutas SKU_Cons'!B13="","",'[3]Motor Rutas SKU_Cons'!B13) -> Planta Hermosillo | D9: ='[3]Motor Rutas SKU_Cons'!A13 -> 401307 | E9: =IF('[3]Motor Rutas SKU_Cons'!N13="","s/d","Agua "&TEXT('[3]Motor Rutas SKU_Cons'!N13,"0%")&" · Colas "&TEXT('[3]Motor Rutas SKU_Cons'!O13,"0%")&" · Resto "&TEXT('[3]Motor Rutas SKU_Cons'!P13,"0%")) -> Agua 85% · Colas 8% · Resto 7% | F9: ='[3]Motor Rutas SKU_Cons'!CH13 -> 0.00066498062 | G9: ='[3]Motor Rutas SKU_Cons'!CG13 | H9: ='[3]Motor Rutas SKU_Cons'!BX13 -> 0 | I9: ='[3]Motor Rutas SKU_Cons'!BW13 -> 0
A10: =IF('[3]Motor Rutas SKU_Cons'!C14="","",'[3]Motor Rutas SKU_Cons'!C14) -> Pacifico | B10: =IF('[3]Motor Rutas SKU_Cons'!D14="","",'[3]Motor Rutas SKU_Cons'!D14) -> No está en EERR | C10: =IF('[3]Motor Rutas SKU_Cons'!B14="","",'[3]Motor Rutas SKU_Cons'!B14) -> Sucursal Cajeme | D10: ='[3]Motor Rutas SKU_Cons'!A14 -> 404304 | E10: =IF('[3]Motor Rutas SKU_Cons'!N14="","s/d","Agua "&TEXT('[3]Motor Rutas SKU_Cons'!N14,"0%")&" · Colas "&TEXT('[3]Motor Rutas SKU_Cons'!O14,"0%")&" · Resto "&TEXT('[3]Motor Rutas SKU_Cons'!P14,"0%")) -> Agua 85% · Colas 8% · Resto 7% | F10: ='[3]Motor Rutas SKU_Cons'!CH14 | G10: ='[3]Motor Rutas SKU_Cons'!CG14 | H10: ='[3]Motor Rutas SKU_Cons'!BX14 -> 0 | I10: ='[3]Motor Rutas SKU_Cons'!BW14 -> 0
A11: =IF('[3]Motor Rutas SKU_Cons'!C15="","",'[3]Motor Rutas SKU_Cons'!C15) -> Pacifico | B11: =IF('[3]Motor Rutas SKU_Cons'!D15="","",'[3]Motor Rutas SKU_Cons'!D15) -> No está en EERR | C11: =IF('[3]Motor Rutas SKU_Cons'!B15="","",'[3]Motor Rutas SKU_Cons'!B15) -> Sucursal Guaymas | D11: ='[3]Motor Rutas SKU_Cons'!A15 -> 406300 | E11: =IF('[3]Motor Rutas SKU_Cons'!N15="","s/d","Agua "&TEXT('[3]Motor Rutas SKU_Cons'!N15,"0%")&" · Colas "&TEXT('[3]Motor Rutas SKU_Cons'!O15,"0%")&" · Resto "&TEXT('[3]Motor Rutas SKU_Cons'!P15,"0%")) -> Agua 85% · Colas 8% · Resto 7% | F11: ='[3]Motor Rutas SKU_Cons'!CH15 | G11: ='[3]Motor Rutas SKU_Cons'!CG15 | H11: ='[3]Motor Rutas SKU_Cons'!BX15 -> 0 | I11: ='[3]Motor Rutas SKU_Cons'!BW15 -> 0
A12: =IF('[3]Motor Rutas SKU_Cons'!C16="","",'[3]Motor Rutas SKU_Cons'!C16) -> Pacifico | B12: =IF('[3]Motor Rutas SKU_Cons'!D16="","",'[3]Motor Rutas SKU_Cons'!D16) -> Mexicali | C12: =IF('[3]Motor Rutas SKU_Cons'!B16="","",'[3]Motor Rutas SKU_Cons'!B16) -> Planta Mexicali | D12: ='[3]Motor Rutas SKU_Cons'!A16 -> 407300 | E12: =IF('[3]Motor Rutas SKU_Cons'!N16="","s/d","Agua "&TEXT('[3]Motor Rutas SKU_Cons'!N16,"0%")&" · Colas "&TEXT('[3]Motor Rutas SKU_Cons'!O16,"0%")&" · Resto "&TEXT('[3]Motor Rutas SKU_Cons'!P16,"0%")) -> Agua 85% · Colas 8% · Resto 7% | F12: ='[3]Motor Rutas SKU_Cons'!CH16 -> 0.093449719 | G12: ='[3]Motor Rutas SKU_Cons'!CG16 | H12: ='[3]Motor Rutas SKU_Cons'!BX16 -> 0 | I12: ='[3]Motor Rutas SKU_Cons'!BW16 -> 0
A13: =IF('[3]Motor Rutas SKU_Cons'!C17="","",'[3]Motor Rutas SKU_Cons'!C17) -> Pacifico | B13: =IF('[3]Motor Rutas SKU_Cons'!D17="","",'[3]Motor Rutas SKU_Cons'!D17) -> Mexicali | C13: =IF('[3]Motor Rutas SKU_Cons'!B17="","",'[3]Motor Rutas SKU_Cons'!B17) -> Planta Mexicali | D13: ='[3]Motor Rutas SKU_Cons'!A17 -> 407301 | E13: =IF('[3]Motor Rutas SKU_Cons'!N17="","s/d","Agua "&TEXT('[3]Motor Rutas SKU_Cons'!N17,"0%")&" · Colas "&TEXT('[3]Motor Rutas SKU_Cons'!O17,"0%")&" · Resto "&TEXT('[3]Motor Rutas SKU_Cons'!P17,"0%")) -> Agua 85% · Colas 8% · Resto 7% | F13: ='[3]Motor Rutas SKU_Cons'!CH17 -> 0.17389948 | G13: ='[3]Motor Rutas SKU_Cons'!CG17 | H13: ='[3]Motor Rutas SKU_Cons'!BX17 -> 0 | I13: ='[3]Motor Rutas SKU_Cons'!BW17 -> 0
... A717: =IF('[3]Motor Rutas SKU_Cons'!C721="","",'[3]Motor Rutas SKU_Cons'!C721) -> Occidente | B717: =IF('[3]Motor Rutas SKU_Cons'!D721="","",'[3]Motor Rutas SKU_Cons'!D721) -> San Luis | C717: =IF('[3]Motor Rutas SKU_Cons'!B721="","",'[3]Motor Rutas SKU_Cons'!B721) -> Planta San Luis | D717: ='[3]Motor Rutas SKU_Cons'!A721 -> 916399 | E717: =IF('[3]Motor Rutas SKU_Cons'!N721="","s/d","Agua "&TEXT('[3]Motor Rutas SKU_Cons'!N721,"0%")&" · Colas "&TEXT('[3]Motor Rutas SKU_Cons'!O721,"0%")&" · Resto "&TEXT('[3]Motor Rutas SKU_Cons'!P721,"0%")) -> Agua 85% · Colas 8% · Resto 7% | F717: ='[3]Motor Rutas SKU_Cons'!CH721 -> 0.0060561904 | G717: ='[3]Motor Rutas SKU_Cons'!CG721 -> 0 | H717: ='[3]Motor Rutas SKU_Cons'!BX721 -> 0 | I717: ='[3]Motor Rutas SKU_Cons'!BW721 -> 3.3682753

Sheet Base de datos Rutas
A1: Base Maestra Rutas — Canal Hogar (789 rutas, ventana ene-2025 a may-2026)
AC2: Agregar | DB2: Incremental | DD2: Incremental | DJ2: Incremental | DL2: Incremental | DR2: Incremental | DT2: Incremental
A3: Identificación | I3: Rentabilidad y volumen (Costo de Servir) | AK3: Potencial y palancas de crecimiento | BD3: Saturación de rutas | BR3: Descripción de Mercado (+NSE) | CK3: Saturación | CW3: Atractividad Caso 90 | DE3: Atractividad Caso 85 | DM3: Atractividad Caso 70
A4: Llaves de cruce y calidad de dato | I4: Rutas | J4: Volumen [CU] | N4: Venta por producto y productividad | R4: Costos (heredado del CeDi) | W4: Venta, CDS y cuadrante | Z4: Operación de ruta | AB4: Mezcla (%) | AK4: Clientes | AM4: Efectividad vs. benchmark | AO4: Brecha de Efectividad (escenario) | AR4: Ingreso y uplift | AU4: Potencial anualizado — Efectividad | AX4: Palanca de ticket | BC4: Total palancas | BD4: Elegibilidad y comparación vs. estándar de su Territorio EERR | BN4: Resultado | BQ4: Capacidad | BR4: Descripción de Mercado (+NSE) | CK4: Potencial | CQ4: Capacidades
A5: Región | B5: Territorio EERR | C5: CeDi | D5: Ruta | E5: Ruta ID | F5: Estatus de ruta | G5: Código de ruta válido | H5: Elegible para estándar | I5: Rutas Hogar del CeDi | J5: Cajas Unidad Garrafón | K5: Cajas Unidad Otros Productos | L5: Volumen Total en Cajas Unidad [CU] | M5: Venta Ingreso | N5: Venta GFN [MXN] | O5: Venta OP [MXN] | P5: Venta MC [MXN] | Q5: Ingreso / Ruta | R5: Costos de Venta Variable | S5: GOD | T5: GOC | U5: Costo-De-Servir (Cedis) (miles) | V5: CDS / Ruta | W5: Venta ruta (promedio cedis) | X5: %CDS vs. Venta Neta | Y5: Cuadrante | Z5: Número de clientes x ruta | AA5: Frecuencia Conv. [/semana] | AB5: % Venta Conv. | AC5: % Venta Web. | AD5: CU conv | AE5: CU web | AF5: Ing conv | AG5: Ing web | AH5: % Venta GFN (ingreso) | AI5: % Venta OP (ingreso) | AJ5: % Venta MC (ingreso) | AK5: Ctes. programados (periodo) | AL5: Ctes. con compra (periodo) | AM5: Efectividad actual | AN5: Benchmark p75 del CeDi | AO5: Ctes. increm. (100%) | AP5: Ctes. increm. (escenario) | AQ5: Efectividad objetivo (escenario) | AR5: Ingreso actual (periodo) | AS5: Ingreso increm. Efectividad (periodo) | AT5: Uplift Efectividad % | AU5: Anualizado Efectividad | AV5: % del potencial del canal | AW5: Ranking por potencial | AX5: Ticket $ / CC | AY5: Ticket p75 de su CeDi | AZ5: Brecha de ticket ($/CC) | BA5: Ruta con brecha de ticket | BB5: Anualizado ticket | BC5: Anualizado ambas palancas | BD5: Elegible (saturación) | BE5: Clientes atiende/día (real) | BF5: Estándar territorio (ideal) — clientes | BG5: Cumple (clientes) | BH5: Efectividad de compra (real) | BI5: Estándar territorio (ideal) — efectividad | BJ5: Cumple (efectividad) | BK5: Volumen CU/día (real) | BL5: Estándar territorio (ideal) — volumen | BM5: Cumple (volumen) | BN5: # Indicadores cumplidos (0-3) | BO5: Zona de saturación | BP5: Saturada (Sí/No) | BQ5: Capacidad adicional (clientes) | BR5: Manzanas | BS5: Población | BT5: Hogares | BU5: Personas por hogar | BV5: Hogares por manzana | BW5: Hogares A/B | BX5: Hogares C+ | BY5: Hogares A/B + C+ | BZ5: % A/B + C+ | CA5: % NSE A/B | CB5: % NSE C+ | CC5: % NSE C | CD5: % NSE C- | CE5: % NSE D+ | CF5: % NSE D | CG5: % NSE E | CH5: % NSE N/D | CI5: Comercio detalle / 1000 hab | CJ5: Comercio proximidad / 1000 hab | CK5: Clientes actuales (Total) | CL5: Clientes potencial | CM5: Delta clientes | CN5: Horas actuales | CO5: Jornada completa | CP5: Delta Horas | CQ5: Capacidad instalada | CR5: Capacidad Utilizada | CS5: Delta Capacidad | CT5: Saturada | CU5: Que tan saturada | CV5: Clientes actuales (Foco) | CW5: Hogares totales ABC+ | CX5: % Hogares totales ABC+ | CY5: Hogares potenciales a captutrar | CZ5: Hogares actual + potencial | DA5: potencial Ingreso /horar | DB5: Potencial de Ingreso | DC5: potencial CU/ hogar | DD5: Potencial CU | DE5: Hogares totales ABC+ | DF5: % Hogares totales ABC+ | DG5: Hogares potenciales a captutrar | DH5: Hogares actual + potencial | DI5: potencial Ingreso /horar | DJ5: Potencial de Ingreso | DK5: potencial CU/ hogar | DL5: Potencial CU | DM5: Hogares totales ABC+ | DN5: % Hogares totales ABC+ | DO5: Hogares potenciales a captutrar | DP5: Hogares actual + potencial | DQ5: potencial Ingreso /horar | DR5: Potencial de Ingreso | DS5: potencial CU/ hogar | DT5: Potencial CU
A6: Noreste | B6: Laredo | C6: Suc. Nuevo Laredo | D6: 105300 | E6: Noreste|Suc. Nuevo Laredo|105300 | F6: Activa | G6: Sí | H6: Sí | I6: 3 | J6: 35033.79 | K6: 30787.417 | L6: 65821.208 | M6: 4663587 | N6: 521961 | O6: 4141626 | P6: 0 | Q6: 11077.4 | R6: 688.35454 | S6: 2836.8939 | T6: 464.31479 | U6: =IFERROR(INDEX('Rentabilidad datos'!$N$2:$N$61,MATCH($C6,'Rentabilidad datos'!$C$2:$C$61,0)),"") -> 3989.5633 | V6: =IFERROR(INDEX('Rentabilidad datos'!$O$2:$O$61,MATCH($C6,'Rentabilidad datos'!$C$2:$C$61,0)),"") -> 1329.8544 | W6: =IFERROR(INDEX('Rentabilidad datos'!$M$2:$M$61,MATCH($C6,'Rentabilidad datos'!$C$2:$C$61,0)),"") -> 2708.9427 | X6: =IFERROR(INDEX('Rentabilidad datos'!$P$2:$P$61,MATCH($C6,'Rentabilidad datos'!$C$2:$C$61,0)),"") -> 0.49091271 | Y6: C4 | Z6: 36 | AA6: 1 | AB6: 1 | AC6: 0 | AD6: =_xlfn.XLOOKUP(Table1[[#This Row],[Ruta]],#REF!,#REF!) -> #REF! | AE6: =_xlfn.XLOOKUP(Table1[[#This Row],[Ruta]],#REF!,#REF!) -> #REF! | AF6: =_xlfn.XLOOKUP(Table1[[#This Row],[Ruta]],#REF!,#REF!) -> #REF! | AG6: =_xlfn.XLOOKUP(Table1[[#This Row],[Ruta]],#REF!,#REF!) -> #REF! | AH6: 0.11192265 | AI6: 0.88807735 | AJ6: 0 | AK6: 15156 | AL6: 5829 | AM6: 0.38460016 | AN6: 0.51668553 | AO6: 2001.8858 | AP6: 1000.9429 | AQ6: 0.45064284 | AR6: 4663585.2 | AS6: 800820.48 | AT6: 0.17171778 | AU6: 562738.72 | AV6: 0.0025599517 | AW6: 132 | AX6: 800.06608 | AY6: 754.63815 | AZ6: 0 | BA6: No | BB6: 0 | BC6: 562738.72 | BD6: Sí | BE6: 36 | BF6: 36 | BG6: Sí | BH6: 0.38460016 | BI6: 0.38460016 | BJ6: Sí | BK6: 156.34491 | BL6: 156.34491 | BM6: Sí | BN6: 3 | BO6: Rojo - Saturada | BP6: Sí | BQ6: 584.47039 | BR6: #N/A | BS6: #N/A | BT6: #N/A | BU6: #N/A | BV6: #N/A | BW6: #N/A | BX6: #N/A | BY6: #N/A | BZ6: #N/A | CA6: #N/A | CB6: #N/A | CC6: #N/A | CD6: #N/A | CE6: #N/A | CF6: #N/A | CG6: #N/A | CH6: #N/A | CI6: #N/A | CJ6: #N/A | CM6: =CL6-CK6 -> 0 | CP6: =CO6-CN6 -> 0 | CS6: =CQ6-CR6 -> 0 | CX6: =((CW6-CY6)/BT6)*100 -> #N/A | CZ6: =((CW6)/BT6)*100 -> #N/A | DA6: =DB6/(CY6+BT6) -> #N/A | DC6: =DD6/(CY6+BT6) -> #N/A
A7: Noreste | B7: Laredo | C7: Suc. Nuevo Laredo | D7: 105301 | E7: Noreste|Suc. Nuevo Laredo|105301 | F7: Activa | G7: Sí | H7: Sí | I7: 3 | J7: 40563.958 | K7: 13839.586 | L7: 54403.545 | M7: 2780293 | N7: 624714 | O7: 2155579 | P7: 0 | Q7: 6864.9177 | R7: 688.35454 | S7: 2836.8939 | T7: 464.31479 | U7: =IFERROR(INDEX('Rentabilidad datos'!$N$2:$N$61,MATCH($C7,'Rentabilidad datos'!$C$2:$C$61,0)),"") -> 3989.5633 | V7: =IFERROR(INDEX('Rentabilidad datos'!$O$2:$O$61,MATCH($C7,'Rentabilidad datos'!$C$2:$C$61,0)),"") -> 1329.8544 | W7: =IFERROR(INDEX('Rentabilidad datos'!$M$2:$M$61,MATCH($C7,'Rentabilidad datos'!$C$2:$C$61,0)),"") -> 2708.9427 | X7: =IFERROR(INDEX('Rentabilidad datos'!$P$2:$P$61,MATCH($C7,'Rentabilidad datos'!$C$2:$C$61,0)),"") -> 0.49091271 | Y7: C4 | Z7: 25.111111 | AA7: 1 | AB7: 1 | AC7: 0 | AD7: =_xlfn.XLOOKUP(Table1[[#This Row],[Ruta]],#REF!,#REF!) -> #REF! | AE7: =_xlfn.XLOOKUP(Table1[[#This Row],[Ruta]],#REF!,#REF!) -> #REF! | AF7: =_xlfn.XLOOKUP(Table1[[#This Row],[Ruta]],#REF!,#REF!) -> #REF! | AG7: =_xlfn.XLOOKUP(Table1[[#This Row],[Ruta]],#REF!,#REF!) -> #REF! | AH7: 0.22469358 | AI7: 0.77530642 | AJ7: 0 | AK7: 10170 | AL7: 6598 | AM7: 0.64877089 | AN7: 0.51668553 | AO7: 0 | AP7: 0 | AQ7: 0.64877089 | AR7: 2780291.7 | AS7: 0 | AT7: 0 | AU7: 0 | AV7: 0 | AW7: 490 | AX7: 421.38401 | AY7: 754.63815 | AZ7: 333.25414 | BA7: Sí | BB7: 772555.15 | BC7: 772555.15 | BD7: Sí | BE7: 25.111111 | BF7: 36 | BG7: No | BH7: 0.64877089 | BI7: 0.38460016 | BJ7: Sí | BK7: 134.32974 | BL7: 156.34491 | BM7: No | BN7: 1 | BO7: Verde - Con espacio | BP7: No | BQ7: 0 | BR7: #N/A | BS7: #N/A | BT7: #N/A | BU7: #N/A | BV7: #N/A | BW7: #N/A | BX7: #N/A | BY7: #N/A | BZ7: #N/A | CA7: #N/A | CB7: #N/A | CC7: #N/A | CD7: #N/A | CE7: #N/A | CF7: #N/A | CG7: #N/A | CH7: #N/A | CI7: #N/A | CJ7: #N/A | CM7: =CL7-CK7 -> 0 | CP7: =CO7-CN7 -> 0 | CS7: =CQ7-CR7 -> 0 | CX7: =((CW7-CY7)/BT7)*100 -> #N/A | CZ7: =((CW7)/BT7)*100 -> #N/A | DA7: =DB7/(CY7+BT7) -> #N/A | DC7: =DD7/(CY7+BT7) -> #N/A
A8: Noreste | B8: Laredo | C8: Suc. Nuevo Laredo | D8: 105302 | E8: Noreste|Suc. Nuevo Laredo|105302 | F8: Activa | G8: Sí | H8: Sí | I8: 3 | J8: 27946.722 | K8: 14840.407 | L8: 42787.129 | M8: 2616989 | N8: 414264 | O8: 2202725 | P8: 0 | Q8: 6260.7313 | R8: 688.35454 | S8: 2836.8939 | T8: 464.31479 | U8: =IFERROR(INDEX('Rentabilidad datos'!$N$2:$N$61,MATCH($C8,'Rentabilidad datos'!$C$2:$C$61,0)),"") -> 3989.5633 | V8: =IFERROR(INDEX('Rentabilidad datos'!$O$2:$O$61,MATCH($C8,'Rentabilidad datos'!$C$2:$C$61,0)),"") -> 1329.8544 | W8: =IFERROR(INDEX('Rentabilidad datos'!$M$2:$M$61,MATCH($C8,'Rentabilidad datos'!$C$2:$C$61,0)),"") -> 2708.9427 | X8: =IFERROR(INDEX('Rentabilidad datos'!$P$2:$P$61,MATCH($C8,'Rentabilidad datos'!$C$2:$C$61,0)),"") -> 0.49091271 | Y8: C4 | Z8: 41.992823 | AA8: 1 | AB8: 1 | AC8: 0 | AD8: =_xlfn.XLOOKUP(Table1[[#This Row],[Ruta]],#REF!,#REF!) -> #REF! | AE8: =_xlfn.XLOOKUP(Table1[[#This Row],[Ruta]],#REF!,#REF!) -> #REF! | AF8: =_xlfn.XLOOKUP(Table1[[#This Row],[Ruta]],#REF!,#REF!) -> #REF! | AG8: =_xlfn.XLOOKUP(Table1[[#This Row],[Ruta]],#REF!,#REF!) -> #REF! | AH8: 0.15829795 | AI8: 0.84170205 | AJ8: 0 | AK8: 17553 | AL8: 3690 | AM8: 0.21022048 | AN8: 0.51668553 | AO8: 5379.381 | AP8: 2689.6905 | AQ8: 0.363453 | AR8: 2616985.7 | AS8: 1907556 | AT8: 0.72891342 | AU8: 1340444.7 | AV8: 0.00609781 | AW8: 19 | AX8: 709.21021 | AY8: 754.63815 | AZ8: 45.427937 | BA8: Sí | BB8: 58896.707 | BC8: 1399341.4 | BD8: Sí | BE8: 41.992823 | BF8: 36 | BG8: Sí | BH8: 0.21022048 | BI8: 0.38460016 | BJ8: No | BK8: 102.36155 | BL8: 156.34491 | BM8: No | BN8: 1 | BO8: Verde - Con espacio | BP8: No | BQ8: 2642.6796 | BR8: #N/A | BS8: #N/A | BT8: #N/A | BU8: #N/A | BV8: #N/A | BW8: #N/A | BX8: #N/A | BY8: #N/A | BZ8: #N/A | CA8: #N/A | CB8: #N/A | CC8: #N/A | CD8: #N/A | CE8: #N/A | CF8: #N/A | CG8: #N/A | CH8: #N/A | CI8: #N/A | CJ8: #N/A | CM8: =CL8-CK8 -> 0 | CP8: =CO8-CN8 -> 0 | CS8: =CQ8-CR8 -> 0 | CX8: =((CW8-CY8)/BT8)*100 -> #N/A | CZ8: =((CW8)/BT8)*100 -> #N/A | DA8: =DB8/(CY8+BT8) -> #N/A | DC8: =DD8/(CY8+BT8) -> #N/A
A9: Noreste | B9: Matamoros | C9: Planta Matamoros | D9: 101340 | E9: Noreste|Planta Matamoros|101340 | F9: Activa | G9: Sí | H9: Sí | I9: 2 | J9: 35378.986 | K9: 11093.503 | L9: 46472.488 | M9: 2161457 | N9: 538003 | O9: 1623454 | P9: 0 | Q9: 4901.1325 | R9: 688.34136 | S9: 2977.2563 | T9: 315.23993 | U9: =IFERROR(INDEX('Rentabilidad datos'!$N$2:$N$61,MATCH($C9,'Rentabilidad datos'!$C$2:$C$61,0)),"") -> 3980.8376 | V9: =IFERROR(INDEX('Rentabilidad datos'!$O$2:$O$61,MATCH($C9,'Rentabilidad datos'!$C$2:$C$61,0)),"") -> 1990.4188 | W9: =IFERROR(INDEX('Rentabilidad datos'!$M$2:$M$61,MATCH($C9,'Rentabilidad datos'!$C$2:$C$61,0)),"") -> 2934.503 | X9: =IFERROR(INDEX('Rentabilidad datos'!$P$2:$P$61,MATCH($C9,'Rentabilidad datos'!$C$2:$C$61,0)),"") -> 0.67828139 | Y9: C3 | Z9: 30.244898 | AA9: 1 | AB9: 1 | AC9: 0 | AD9: =_xlfn.XLOOKUP(Table1[[#This Row],[Ruta]],#REF!,#REF!) -> #REF! | AE9: =_xlfn.XLOOKUP(Table1[[#This Row],[Ruta]],#REF!,#REF!) -> #REF! | AF9: =_xlfn.XLOOKUP(Table1[[#This Row],[Ruta]],#REF!,#REF!) -> #REF! | AG9: =_xlfn.XLOOKUP(Table1[[#This Row],[Ruta]],#REF!,#REF!) -> #REF! | AH9: 0.24890757 | AI9: 0.75109243 | AJ9: 0 | AK9: 13338 | AL9: 7421 | AM9: 0.55638027 | AN9: 0.50471056 | AO9: 0 | AP9: 0 | AQ9: 0.55638027 | AR9: 2161399.5 | AS9: 0 | AT9: 0 | AU9: 0 | AV9: 0 | AW9: 490 | AX9: 291.25447 | AY9: 1096.2918 | AZ9: 805.03735 | BA9: Sí | BB9: 2099037 | BC9: 2099037 | BD9: Sí | BE9: 30.244898 | BF9: 25.444444 | BG9: Sí | BH9: 0.55638027 | BI9: 0.34970145 | BJ9: Sí | BK9: 105.37979 | BL9: 174.22352 | BM9: No | BN9: 2 | BO9: Amarillo - Cerca del tope | BP9: No | BQ9: 0 | BR9: 2716 | BS9: 154754 | BT9: 47495 | BU9: 3.2583219 | BV9: 17.487113 | BW9: 1668 | BX9: 6941 | BY9: 8609 | BZ9: 0.18126119 | CA9: 0.035119486 | CB9: 0.1461417 | CC9: 0.21842299 | CD9: 0.042109696 | CE9: 0.033519318 | CF9: 0.52447626 | CG9: 0.00021054848 | CH9: 0 | CI9: 3.9611254 | CJ9: 0.83358104 | CK9: 168 | CL9: 370.78 | CM9: =CL9-CK9 -> 202.78 | CN9: 3.89 | CO9: 9.45 | CP9: =CO9-CN9 -> 5.56 | CQ9: 677.25 | CR9: 105.38 | CS9: =CQ9-CR9 -> 571.87 | CT9: No | CU9: 41.18 | CV9: 66 | CW9: 8609 | CX9: =((CW9-CY9)/BT9)*100 -> 17.699168 | CY9: 202.78 | CZ9: =((CW9)/BT9)*100 -> 18.126119 | DA9: =DB9/(CY9+BT9) -> 58.952016 | DB9: 2811880.3 | DC9: =DD9/(CY9+BT9) -> 1.0568639 | DD9: 50410.06 | DE9: 8609 | DF9: 17.866 | DG9: 123.4 | DH9: 18.126 | DI9: 115.262 | DJ9: 5488571 | DK9: 1.824 | DL9: 86870.6 | DM9: 8609 | DN9: 17.904 | DO9: 105.6 | DP9: 18.126 | DQ9: 112.011 | DR9: 5331784 | DS9: 1.767 | DT9: 84097.6
A10: Noreste | B10: Matamoros | C10: Planta Matamoros | D10: 101341 | E10: Noreste|Planta Matamoros|101341 | F10: Activa | G10: Sí | H10: Sí | I10: 2 | J10: 37876.367 | K10: 38956.206 | L10: 76832.573 | M10: 5354783 | N10: 557988 | O10: 4796795 | P10: 0 | Q10: 12142.49 | R10: 688.34136 | S10: 2977.2563 | T10: 315.23993 | U10: =IFERROR(INDEX('Rentabilidad datos'!$N$2:$N$61,MATCH($C10,'Rentabilidad datos'!$C$2:$C$61,0)),"") -> 3980.8376 | V10: =IFERROR(INDEX('Rentabilidad datos'!$O$2:$O$61,MATCH($C10,'Rentabilidad datos'!$C$2:$C$61,0)),"") -> 1990.4188 | W10: =IFERROR(INDEX('Rentabilidad datos'!$M$2:$M$61,MATCH($C10,'Rentabilidad datos'!$C$2:$C$61,0)),"") -> 2934.503 | X10: =IFERROR(INDEX('Rentabilidad datos'!$P$2:$P$61,MATCH($C10,'Rentabilidad datos'!$C$2:$C$61,0)),"") -> 0.67828139 | Y10: C3 | Z10: 25.444444 | AA10: 1 | AB10: 1 | AC10: 0 | AD10: =_xlfn.XLOOKUP(Table1[[#This Row],[Ruta]],#REF!,#REF!) -> #REF! | AE10: =_xlfn.XLOOKUP(Table1[[#This Row],[Ruta]],#REF!,#REF!) -> #REF! | AF10: =_xlfn.XLOOKUP(Table1[[#This Row],[Ruta]],#REF!,#REF!) -> #REF! | AG10: =_xlfn.XLOOKUP(Table1[[#This Row],[Ruta]],#REF!,#REF!) -> #REF! | AH10: 0.10420366 | AI10: 0.89579634 | AJ10: 0 | AK10: 11221 | AL10: 3924 | AM10: 0.34970145 | AN10: 0.50471056 | AO10: 1739.3572 | AP10: 869.67862 | AQ10: 0.42720601 | AR10: 5354838 | AS10: 1186796.1 | AT10: 0.22163064 | AU10: 833964.86 | AV10: 0.0037937851 | AW10: 69 | AX10: 1364.6376 | AY10: 1096.2918 | AZ10: 0 | BA10: No | BB10: 0 | BC10: 833964.86 | BD10: Sí | BE10: 25.444444 | BF10: 25.444444 | BG10: Sí | BH10: 0.34970145 | BI10: 0.34970145 | BJ10: Sí | BK10: 174.22352 | BL10: 174.22352 | BM10: Sí | BN10: 3 | BO10: Rojo - Saturada | BP10: Sí | BQ10: 1004.1185 | BR10: 3972 | BS10: 293716 | BT10: 85066 | BU10: 3.4528014 | BV10: 21.416415 | BW10: 1310 | BX10: 5532 | BY10: 6842 | BZ10: 0.080431665 | CA10: 0.015399807 | CB10: 0.065031858 | CC10: 0.22031129 | CD10: 0.08491054 | CE10: 0.036089625 | CF10: 0.57825688 | CG10: 0 | CH10: 0 | CI10: 4.4669 | CJ10: 0.45622302 | CK10: 149 | CL10: 347.64 | CM10: =CL10-CK10 -> 198.64 | CN10: 3.55 | CO10: 9.45 | CP10: =CO10-CN10 -> 5.9 | CQ10: 677.25 | CR10: 174.22 | CS10: =CQ10-CR10 -> 503.03 | CT10: No | CU10: 37.59 | CV10: 60 | CW10: 6842 | CX10: =((CW10-CY10)/BT10)*100 -> 7.8096537 | CY10: 198.64 | CZ10: =((CW10)/BT10)*100 -> 8.0431665 | DA10: =DB10/(CY10+BT10) -> 14.96277 | DB10: 1275795.2 | DC10: =DD10/(CY10+BT10) -> 0.44938336 | DD10: 38316.51 | DE10: 6842 | DF10: 7.899 | DG10: 122.7 | DH10: 8.043 | DI10: 20.724 | DJ10: 1765465 | DK10: 0.624 | DL10: 53134.6 | DM10: 6842 | DN10: 7.923 | DO10: 102.5 | DP10: 8.043 | DQ10: 19.251 | DR10: 1639556 | DS10: 0.58 | DT10: 49393.4
A11: Noreste | B11: Monclova | C11: Sucursal Monclova | D11: 206300 | E11: Noreste|Sucursal Monclova|206300 | F11: Activa | G11: Sí | H11: Sí | I11: 3 | J11: 201333.34 | K11: 5841.6235 | L11: 207174.96 | M11: 3983960 | N11: 3131217 | O11: 852743 | P11: 0 | Q11: 9075.0807 | R11: 1365.8094 | S11: 3238.6465 | T11: 415.65553 | U11: =IFERROR(INDEX('Rentabilidad datos'!$N$2:$N$61,MATCH($C11,'Rentabilidad datos'!$C$2:$C$61,0)),"") -> 5020.1114 | V11: =IFERROR(INDEX('Rentabilidad datos'!$O$2:$O$61,MATCH($C11,'Rentabilidad datos'!$C$2:$C$61,0)),"") -> 1673.3705 | W11: =IFERROR(INDEX('Rentabilidad datos'!$M$2:$M$61,MATCH($C11,'Rentabilidad datos'!$C$2:$C$61,0)),"") -> 2926.366 | X11: =IFERROR(INDEX('Rentabilidad datos'!$P$2:$P$61,MATCH($C11,'Rentabilidad datos'!$C$2:$C$61,0)),"") -> 0.57182542 | Y11: C3 | Z11: 26.476082 | AA11: 1 | AB11: 1 | AC11: 0 | AD11: =_xlfn.XLOOKUP(Table1[[#This Row],[Ruta]],#REF!,#REF!) -> #REF! | AE11: =_xlfn.XLOOKUP(Table1[[#This Row],[Ruta]],#REF!,#REF!) -> #REF! | AF11: =_xlfn.XLOOKUP(Table1[[#This Row],[Ruta]],#REF!,#REF!) -> #REF! | AG11: =_xlfn.XLOOKUP(Table1[[#This Row],[Ruta]],#REF!,#REF!) -> #REF! | AH11: 0.78595593 | AI11: 0.21404407 | AJ11: 0 | AK11: 11623 | AL11: 7614 | AM11: 0.65508044 | AN11: 0.70543489 | AO11: 585.26974 | AP11: 292.63487 | AQ11: 0.68025767 | AR11: 3983960.4 | AS11: 153118.69 | AT11: 0.038433789 | AU11: 107596.92 | AV11: 0.00048946857 | AW11: 389 | AX11: 523.24145 | AY11: 433.47414 | AZ11: 0 | BA11: No | BB11: 0 | BC11: 107596.92 | BD11: Sí | BE11: 26.476082 | BF11: 35.429545 | BG11: No | BH11: 0.65508044 | BI11: 0.75578934 | BJ11: No | BK11: 471.92474 | BL11: 393.27663 | BM11: Sí | BN11: 1 | BO11: Verde - Con espacio | BP11: No | BQ11: 4036.9159 | BR11: 1355 | BS11: 62940 | BT11: 19168 | BU11: 3.2835977 | BV11: 14.146125 | BW11: 2813 | BX11: 6425 | BY11: 9238 | BZ11: 0.48194908 | CA11: 0.14675501 | CB11: 0.33519407 | CC11: 0.11133139 | CD11: 0.014398998 | CE11: 0.023789649 | CF11: 0.36472245 | CG11: 0.0037562604 | CH11: 5.2170284e-05 | CI11: 3.6224976 | CJ11: 0.69907849 | CK11: 116 | CL11: 183.91 | CM11: =CL11-CK11 -> 67.91 | CN11: 2.33 | CO11: 9.45 | CP11: =CO11-CN11 -> 7.12 | CQ11: 846.56 | CR11: 471.92 | CS11: =CQ11-CR11 -> 374.64 | CT11: No | CU11: 55.75 | CV11: 70 | CW11: 9238 | CX11: =((CW11-CY11)/BT11)*100 -> 47.84062 | CY11: 67.91 | CZ11: =((CW11)/BT11)*100 -> 48.194908 | DA11: =DB11/(CY11+BT11) -> 74.466137 | DB11: 1432423.9 | DC11: =DD11/(CY11+BT11) -> 3.6825141 | DD11: 70836.51 | DE11: 9238 | DF11: 47.848 | DG11: 66.5 | DH11: 48.195 | DI11: 190.143 | DJ11: 3657308 | DK11: 9.564 | DL11: 183955.8 | DM11: 9238 | DN11: 47.871 | DO11: 62.2 | DP11: 48.195 | DQ11: 187.332 | DR11: 3602419 | DS11: 9.447 | DT11: 181661.1
A12: Noreste | B12: Monclova | C12: Sucursal Monclova | D12: 206301 | E12: Noreste|Sucursal Monclova|206301 | F12: Activa | G12: Sí | H12: Sí | I12: 3 | J12: 180853.68 | K12: 10231.389 | L12: 191085.07 | M12: 3675477 | N12: 2748420 | O12: 924835 | P12: 2222 | Q12: 8273.0898 | R12: 1365.8094 | S12: 3238.6465 | T12: 415.65553 | U12: =IFERROR(INDEX('Rentabilidad datos'!$N$2:$N$61,MATCH($C12,'Rentabilidad datos'!$C$2:$C$61,0)),"") -> 5020.1114 | V12: =IFERROR(INDEX('Rentabilidad datos'!$O$2:$O$61,MATCH($C12,'Rentabilidad datos'!$C$2:$C$61,0)),"") -> 1673.3705 | W12: =IFERROR(INDEX('Rentabilidad datos'!$M$2:$M$61,MATCH($C12,'Rentabilidad datos'!$C$2:$C$61,0)),"") -> 2926.366 | X12: =IFERROR(INDEX('Rentabilidad datos'!$P$2:$P$61,MATCH($C12,'Rentabilidad datos'!$C$2:$C$61,0)),"") -> 0.57182542 | Y12: C3 | Z12: 39.218468 | AA12: 1 | AB12: 1 | AC12: 0 | AD12: =_xlfn.XLOOKUP(Table1[[#This Row],[Ruta]],#REF!,#REF!) -> #REF! | AE12: =_xlfn.XLOOKUP(Table1[[#This Row],[Ruta]],#REF!,#REF!) -> #REF! | AF12: =_xlfn.XLOOKUP(Table1[[#This Row],[Ruta]],#REF!,#REF!) -> #REF! | AG12: =_xlfn.XLOOKUP(Table1[[#This Row],[Ruta]],#REF!,#REF!) -> #REF! | AH12: 0.74777233 | AI12: 0.25162312 | AJ12: 0.00060454738 | AK12: 17413 | AL12: 10706 | AM12: 0.614828 | AN12: 0.70543489 | AO12: 1577.7378 | AP12: 788.86888 | AQ12: 0.66013145 | AR12: 3673251.9 | AS12: 270662.63 | AT12: 0.073684745 | AU12: 190195.36 | AV12: 0.00086521669 | AW12: 317 | AX12: 343.10217 | AY12: 433.47414 | AZ12: 90.371968 | BA12: Sí | BB12: 339940.26 | BC12: 530135.62 | BD12: Sí | BE12: 39.218468 | BF12: 35.429545 | BG12: Sí | BH12: 0.614828 | BI12: 0.75578934 | BJ12: No | BK12: 430.37178 | BL12: 393.27663 | BM12: Sí | BN12: 2 | BO12: Amarillo - Cerca del tope | BP12: No | BQ12: 217.85402 | BR12: 2167 | BS12: 110786 | BT12: 31718 | BU12: 3.4928432 | BV12: 14.636825 | BW12: 197 | BX12: 3940 | BY12: 4137 | BZ12: 0.13043067 | CA12: 0.0062109843 | CB12: 0.12421969 | CC12: 0.054637745 | CD12: 0.074815562 | CE12: 0 | CF12: 0.7390756 | CG12: 0.0010404187 | CH12: 0 | CI12: 5.8400881 | CJ12: 0.59574314 | CK12: 161 | CL12: 229.27 | CM12: =CL12-CK12 -> 68.27 | CN12: 3.62 | CO12: 9.45 | CP12: =CO12-CN12 -> 5.83 | CQ12: 846.56 | CR12: 430.37 | CS12: =CQ12-CR12 -> 416.19 | CT12: No | CU12: 50.84 | CV12: 66 | CW12: 4137 | CX12: =((CW12-CY12)/BT12)*100 -> 12.827826 | CY12: 68.27 | CZ12: =((CW12)/BT12)*100 -> 13.043067 | DA12: =DB12/(CY12+BT12) -> 37.752934 | DB12: 1200025 | DC12: =DD12/(CY12+BT12) -> 1.6840837 | DD12: 53530.74 | DE12: 4137 | DF12: 12.84 | DG12: 64.5 | DH12: 13.043 | DI12: 127.221 | DJ12: 4043396 | DK12: 6.138 | DL12: 195089.6 | DM12: 4137 | DN12: 12.876 | DO12: 53.1 | DP12: 13.043 | DQ12: 121.27 | DR12: 3852866 | DS12: 5.872 | DT12: 186568.9
A13: Noreste | B13: Monclova | C13: Sucursal Monclova | D13: 206302 | E13: Noreste|Sucursal Monclova|206302 | F13: Activa | G13: Sí | H13: Sí | I13: 3 | J13: 161734.52 | K13: 11307.197 | L13: 173041.72 | M13: 4049556 | N13: 2506515 | O13: 1543041 | P13: 0 | Q13: 9203.5315 | R13: 1365.8094 | S13: 3238.6465 | T13: 415.65553 | U13: =IFERROR(INDEX('Rentabilidad datos'!$N$2:$N$61,MATCH($C13,'Rentabilidad datos'!$C$2:$C$61,0)),"") -> 5020.1114 | V13: =IFERROR(INDEX('Rentabilidad datos'!$O$2:$O$61,MATCH($C13,'Rentabilidad datos'!$C$2:$C$61,0)),"") -> 1673.3705 | W13: =IFERROR(INDEX('Rentabilidad datos'!$M$2:$M$61,MATCH($C13,'Rentabilidad datos'!$C$2:$C$61,0)),"") -> 2926.366 | X13: =IFERROR(INDEX('Rentabilidad datos'!$P$2:$P$61,MATCH($C13,'Rentabilidad datos'!$C$2:$C$61,0)),"") -> 0.57182542 | Y13: C3 | Z13: 35.429545 | AA13: 1 | AB13: 1 | AC13: 0 | AD13: =_xlfn.XLOOKUP(Table1[[#This Row],[Ruta]],#REF!,#REF!) -> #REF! | AE13: =_xlfn.XLOOKUP(Table1[[#This Row],[Ruta]],#REF!,#REF!) -> #REF! | AF13: =_xlfn.XLOOKUP(Table1[[#This Row],[Ruta]],#REF!,#REF!) -> #REF! | AG13: =_xlfn.XLOOKUP(Table1[[#This Row],[Ruta]],#REF!,#REF!) -> #REF! | AH13: 0.61896045 | AI13: 0.38103955 | AJ13: 0 | AK13: 15589 | AL13: 11782 | AM13: 0.75578934 | AN13: 0.70543489 | AO13: 0 | AP13: 0 | AQ13: 0.75578934 | AR13: 4049553.9 | AS13: 0 | AT13: 0 | AU13: 0 | AV13: 0 | AW13: 490 | AX13: 343.70683 | AY13: 433.47414 | AZ13: 89.767311 | BA13: Sí | BB13: 371602.7 | BC13: 371602.7 | BD13: Sí | BE13: 35.429545 | BF13: 35.429545 | BG13: Sí | BH13: 0.75578934 | BI13: 0.75578934 | BJ13: Sí | BK13: 393.27663 | BL13: 393.27663 | BM13: Sí | BN13: 3 | BO13: Rojo - Saturada | BP13: Sí | BQ13: 0 | BR13: 3002 | BS13: 161465 | BT13: 46741 | BU13: 3.4544618 | BV13: 15.569953 | BW13: 1070 | BX13: 5923 | BY13: 6993 | BZ13: 0.14961169 | CA13: 0.022892108 | CB13: 0.12671958 | CC13: 0.12325367 | CD13: 0.15241437 | CE13: 0.0039579812 | CF13: 0.57076229 | CG13: 0 | CH13: 0 | CI13: 5.3076518 | CJ13: 0.47688354 | CK13: 165 | CL13: 313.52 | CM13: =CL13-CK13 -> 148.52 | CN13: 3.54 | CO13: 9.45 | CP13: =CO13-CN13 -> 5.91 | CQ13: 846.56 | CR13: 393.28 | CS13: =CQ13-CR13 -> 453.28 | CT13: No | CU13: 47.44 | CV13: 102 | CW13: 6993 | CX13: =((CW13-CY13)/BT13)*100 -> 14.643418 | CY13: 148.52 | CZ13: =((CW13)/BT13)*100 -> 14.961169 | DA13: =DB13/(CY13+BT13) -> 81.489118 | DB13: 3820985.6 | DC13: =DD13/(CY13+BT13) -> 3.6734311 | DD13: 172245.42 | DE13: 6993 | DF13: 14.659 | DG13: 141.1 | DH13: 14.961 | DI13: 134.22 | DJ13: 6292506 | DK13: 6.075 | DL13: 284786.9 | DM13: 6993 | DN13: 14.707 | DO13: 118.9 | DP13: 14.961 | DQ13: 125.758 | DR13: 5892995 | DS13: 5.69 | DT13: 266613.7
A14: Noreste | B14: Monterrey | C14: Planta Guadalupe | D14: 701300 | E14: Noreste|Planta Guadalupe|701300 | F14: Activa | G14: Sí | H14: Sí | I14: 22 | J14: 121360.77 | K14: 55272.918 | L14: 176633.69 | M14: 8811435 | N14: 1852259 | O14: 6957834 | P14: 1342 | Q14: 19797.953 | R14: 6394.5727 | S14: 22541.519 | T14: 2275.8097 | U14: =IFERROR(INDEX('Rentabilidad datos'!$N$2:$N$61,MATCH($C14,'Rentabilidad datos'!$C$2:$C$61,0)),"") -> 31211.901 | V14: =IFERROR(INDEX('Rentabilidad datos'!$O$2:$O$61,MATCH($C14,'Rentabilidad datos'!$C$2:$C$61,0)),"") -> 1486.281 | W14: =IFERROR(INDEX('Rentabilidad datos'!$M$2:$M$61,MATCH($C14,'Rentabilidad datos'!$C$2:$C$61,0)),"") -> 3561.4148 | X14: =IFERROR(INDEX('Rentabilidad datos'!$P$2:$P$61,MATCH($C14,'Rentabilidad datos'!$C$2:$C$61,0)),"") -> 0.41732881 | Y14: C2 | Z14: 74.595506 | AA14: 1 | AB14: 0.99938455 | AC14: 0.00061545026 | AD14: =_xlfn.XLOOKUP(Table1[[#This Row],[Ruta]],#REF!,#REF!) -> #REF! | AE14: =_xlfn.XLOOKUP(Table1[[#This Row],[Ruta]],#REF!,#REF!) -> #REF! | AF14: =_xlfn.XLOOKUP(Table1[[#This Row],[Ruta]],#REF!,#REF!) -> #REF! | AG14: =_xlfn.XLOOKUP(Table1[[#This Row],[Ruta]],#REF!,#REF!) -> #REF! | AH14: 0.21021082 | AI14: 0.78963688 | AJ14: 0.00015230209 | AK14: 33195 | AL14: 27229 | AM14: 0.82027414 | AN14: 0.76950938 | AO14: 0 | AP14: 0 | AQ14: 0.82027414 | AR14: 8810089 | AS14: 0 | AT14: 0 | AU14: 0 | AV14: 0 | AW14: 490 | AX14: 323.55536 | AY14: 436.55824 | AZ14: 113.00288 | BA14: Sí | BB14: 1081092.5 | BC14: 1081092.5 | BD14: Sí | BE14: 74.595506 | BF14: 48.897321 | BG14: Sí | BH14: 0.82027414 | BI14: 0.79215712 | BJ14: Sí | BK14: 396.92963 | BL14: 326.54714 | BM14: Sí | BN14: 3 | BO14: Rojo - Saturada | BP14: Sí | BQ14: 0 | BR14: 128 | BS14: 8227 | BT14: 2823 | BU14: 2.9142756 | BV14: 22.054688 | BW14: 1555 | BX14: 1268 | BY14: 2823 | BZ14: 1 | CA14: 0.55083245 | CB14: 0.44916755 | CC14: 0 | CD14: 0 | CE14: 0 | CF14: 0 | CG14: 0 | CH14: 0 | CI14: 0.85085693 | CJ14: 1.7017139 | CK14: 417 | CL14: 739.88 | CM14: =CL14-CK14 -> 322.88 | CN14: 6.46 | CO14: 9.45 | CP14: =CO14-CN14 -> 2.99 | CQ14: 1269.84 | CR14: 396.93 | CS14: =CQ14-CR14 -> 872.91 | CT14: No | CU14: 69.26 | CV14: 474 | CW14: 2823 | CX14: =((CW14-CY14)/BT14)*100 -> 88.562522 | CY14: 322.88 | CZ14: =((CW14)/BT14)*100 -> 100 | DA14: =DB14/(CY14+BT14) -> 1051.2866 | DB14: 3307221.4 | DC14: =DD14/(CY14+BT14) -> 22.084663 | DD14: 69475.7 | DE14: 2823 | DF14: 91.563 | DG14: 238.2 | DH14: 100 | DI14: 2264.077 | DJ14: 6930746 | DK14: 47.362 | DL14: 144982.2 | DM14: 2823 | DN14: 93.052 | DO14: 196.1 | DP14: 100 | DQ14: 2184.689 | DR14: 6595900 | DS14: 45.668 | DT14: 137877.2
A15: Noreste | B15: Monterrey | C15: Planta Guadalupe | D15: 701301 | E15: Noreste|Planta Guadalupe|701301 | F15: Activa | G15: Sí | H15: Sí | I15: 22 | J15: 81082.126 | K15: 40142.275 | L15: 121224.4 | M15: 6501356 | N15: 1227962 | O15: 5273266 | P15: 128 | Q15: 14809.18 | R15: 6394.5727 | S15: 22541.519 | T15: 2275.8097 | U15: =IFERROR(INDEX('Rentabilidad datos'!$N$2:$N$61,MATCH($C15,'Rentabilidad datos'!$C$2:$C$61,0)),"") -> 31211.901 | V15: =IFERROR(INDEX('Rentabilidad datos'!$O$2:$O$61,MATCH($C15,'Rentabilidad datos'!$C$2:$C$61,0)),"") -> 1486.281 | W15: =IFERROR(INDEX('Rentabilidad datos'!$M$2:$M$61,MATCH($C15,'Rentabilidad datos'!$C$2:$C$61,0)),"") -> 3561.4148 | X15: =IFERROR(INDEX('Rentabilidad datos'!$P$2:$P$61,MATCH($C15,'Rentabilidad datos'!$C$2:$C$61,0)),"") -> 0.41732881 | Y15: C2 | Z15: 83.91344 | AA15: 1 | AB15: 0.99880271 | AC15: 0.0011972887 | AD15: =_xlfn.XLOOKUP(Table1[[#This Row],[Ruta]],#REF!,#REF!) -> #REF! | AE15: =_xlfn.XLOOKUP(Table1[[#This Row],[Ruta]],#REF!,#REF!) -> #REF! | AF15: =_xlfn.XLOOKUP(Table1[[#This Row],[Ruta]],#REF!,#REF!) -> #REF! | AG15: =_xlfn.XLOOKUP(Table1[[#This Row],[Ruta]],#REF!,#REF!) -> #REF! | AH15: 0.18887783 | AI15: 0.81110248 | AJ15: 1.96882e-05 | AK15: 36838 | AL15: 21521 | AM15: 0.58420653 | AN15: 0.76950938 | AO15: 6826.1867 | AP15: 3413.0933 | AQ15: 0.67685796 | AR15: 6501229.9 | AS15: 1031053.6 | AT15: 0.15859362 | AU15: 724524.15 | AV15: 0.0032959289 | AW15: 89 | AX15: 302.08772 | AY15: 436.55824 | AZ15: 134.47052 | BA15: Sí | BB15: 1016789.8 | BC15: 1741313.9 | BD15: Sí | BE15: 83.91344 | BF15: 48.897321 | BG15: Sí | BH15: 0.58420653 | BI15: 0.79215712 | BJ15: No | BK15: 276.13759 | BL15: 326.54714 | BM15: No | BN15: 1 | BO15: Verde - Con espacio | BP15: No | BQ15: 0 | BR15: 110 | BS15: 6160 | BT15: 1960 | BU15: 3.1428571 | BV15: 17.818182 | BW15: 1960 | BX15: 0 | BY15: 1960 | BZ15: 1 | CA15: 1 | CB15: 0 | CC15: 0 | CD15: 0 | CE15: 0 | CF15: 0 | CG15: 0 | CH15: 0 | CI15: 0.16233766 | CJ15: 0.64935065 | CK15: 375 | CL15: 515.32 | CM15: =CL15-CK15 -> 140.32 | CN15: 6.98 | CO15: 9.45 | CP15: =CO15-CN15 -> 2.47 | CQ15: 1269.84 | CR15: 276.14 | CS15: =CQ15-CR15 -> 993.7 | CT15: No | CU15: 73.81 | CV15: 401 | CW15: 1960 | CX15: =((CW15-CY15)/BT15)*100 -> 92.840816 | CY15: 140.32 | CZ15: =((CW15)/BT15)*100 -> 100 | DA15: =DB15/(CY15+BT15) -> 1238.9229 | DB15: 2602134.6 | DC15: =DD15/(CY15+BT15) -> 23.434015 | DD15: 49218.93 | DE15: 1960 | DF15: 93.944 | DG15: 118.7 | DH15: 100 | DI15: 3065.636 | DJ15: 6372502 | DK15: 57.899 | DL15: 120354.5 | DM15: 1960 | DN15: 95.013 | DO15: 97.7 | DP15: 100 | DQ15: 2989.292 | DR15: 6151196 | DS15: 56.451 | DT15: 116161
A16: Noreste | B16: Monterrey | C16: Planta Guadalupe | D16: 701302 | E16: Noreste|Planta Guadalupe|701302 | F16: Activa | G16: Sí | H16: Sí | I16: 22 | J16: 56273.862 | K16: 31872.574 | L16: 88146.437 | M16: 4786351 | N16: 813869 | O16: 3972482 | P16: 0 | Q16: 10706.109 | R16: 6394.5727 | S16: 22541.519 | T16: 2275.8097 | U16: =IFERROR(INDEX('Rentabilidad datos'!$N$2:$N$61,MATCH($C16,'Rentabilidad datos'!$C$2:$C$61,0)),"") -> 31211.901 | V16: =IFERROR(INDEX('Rentabilidad datos'!$O$2:$O$61,MATCH($C16,'Rentabilidad datos'!$C$2:$C$61,0)),"") -> 1486.281 | W16: =IFERROR(INDEX('Rentabilidad datos'!$M$2:$M$61,MATCH($C16,'Rentabilidad datos'!$C$2:$C$61,0)),"") -> 3561.4148 | X16: =IFERROR(INDEX('Rentabilidad datos'!$P$2:$P$61,MATCH($C16,'Rentabilidad datos'!$C$2:$C$61,0)),"") -> 0.41732881 | Y16: C2 | Z16: 75.371365 | AA16: 1 | AB16: 0.99933854 | AC16: 0.00066146423 | AD16: =_xlfn.XLOOKUP(Table1[[#This Row],[Ruta]],#REF!,#REF!) -> #REF! | AE16: =_xlfn.XLOOKUP(Table1[[#This Row],[Ruta]],#REF!,#REF!) -> #REF! | AF16: =_xlfn.XLOOKUP(Table1[[#This Row],[Ruta]],#REF!,#REF!) -> #REF! | AG16: =_xlfn.XLOOKUP(Table1[[#This Row],[Ruta]],#REF!,#REF!) -> #REF! | AH16: 0.17003956 | AI16: 0.82996044 | AJ16: 0 | AK16: 33691 | AL16: 16384 | AM16: 0.48630198 | AN16: 0.76950938 | AO16: 9541.5407 | AP16: 4770.7703 | AQ16: 0.62790568 | AR16: 4785630.6 | AS16: 1393502.5 | AT16: 0.29118471 | AU16: 979217.96 | AV16: 0.0044545552 | AW16: 49 | AX16: 292.09171 | AY16: 436.55824 | AZ16: 144.46653 | BA16: Sí | BB16: 831627.43 | BC16: 1810845.4 | BD16: Sí | BE16: 75.371365 | BF16: 48.897321 | BG16: Sí | BH16: 0.48630198 | BI16: 0.79215712 | BJ16: No | BK16: 197.19561 | BL16: 326.54714 | BM16: No | BN16: 1 | BO16: Verde - Con espacio | BP16: No | BQ16: 1188.3454 | BR16: 460 | BS16: 34849 | BT16: 11761 | BU16: 2.9630984 | BV16: 25.567391 | BW16: 44 | BX16: 8919 | BY16: 8963 | BZ16: 0.76209506 | CA16: 0.0037411785 | CB16: 0.75835388 | CC16: 0.084006462 | CD16: 0.07984015 | CE16: 0 | CF16: 0.074058328 | CG16: 0 | CH16: 0 | CI16: 1.4634566 | CJ16: 1.1765043 | CK16: 701 | CL16: 910.77 | CM16: =CL16-CK16 -> 209.77 | CN16: 8.72 | CO16: 9.45 | CP16: =CO16-CN16 -> 0.73 | CQ16: 634.92 | CR16: 197.2 | CS16: =CQ16-CR16 -> 437.72 | CT16: No | CU16: 92.23 | CV16: 819 | CW16: 8963 | CX16: =((CW16-CY16)/BT16)*100 -> 74.425899 | CY16: 209.77 | CZ16: =((CW16)/BT16)*100 -> 76.209506 | DA16: =DB16/(CY16+BT16) -> 286.79557 | DB16: 3433163.9 | DC16: =DD16/(CY16+BT16) -> 6.3716895 | DD16: 76274.03 | DE16: 8963 | DF16: 74.529 | DG16: 197.6 | DH16: 76.21 | DI16: 724.22 | DJ16: 8660693 | DK16: 16.396 | DL16: 196076.8 | DM16: 8963 | DN16: 74.675 | DO16: 180.4 | DP16: 76.21 | DQ16: 717.794 | DR16: 8571492 | DS16: 16.226 | DT16: 193756.2
A17: Noreste | B17: Monterrey | C17: Planta Guadalupe | D17: 701303 | E17: Noreste|Planta Guadalupe|701303 | F17: Activa | G17: Sí | H17: Sí | I17: 22 | J17: 96143.908 | K17: 49380.95 | L17: 145524.86 | M17: 7393780 | N17: 1369314 | O17: 6023284 | P17: 1182 | Q17: 16852.328 | R17: 6394.5727 | S17: 22541.519 | T17: 2275.8097 | U17: =IFERROR(INDEX('Rentabilidad datos'!$N$2:$N$61,MATCH($C17,'Rentabilidad datos'!$C$2:$C$61,0)),"") -> 31211.901 | V17: =IFERROR(INDEX('Rentabilidad datos'!$O$2:$O$61,MATCH($C17,'Rentabilidad datos'!$C$2:$C$61,0)),"") -> 1486.281 | W17: =IFERROR(INDEX('Rentabilidad datos'!$M$2:$M$61,MATCH($C17,'Rentabilidad datos'!$C$2:$C$61,0)),"") -> 3561.4148 | X17: =IFERROR(INDEX('Rentabilidad datos'!$P$2:$P$61,MATCH($C17,'Rentabilidad datos'!$C$2:$C$61,0)),"") -> 0.41732881 | Y17: C2 | Z17: 92.468182 | AA17: 1 | AB17: 0.98865127 | AC17: 0.011348728 | AD17: =_xlfn.XLOOKUP(Table1[[#This Row],[Ruta]],#REF!,#REF!) -> #REF! | AE17: =_xlfn.XLOOKUP(Table1[[#This Row],[Ruta]],#REF!,#REF!) -> #REF! | AF17: =_xlfn.XLOOKUP(Table1[[#This Row],[Ruta]],#REF!,#REF!) -> #REF! | AG17: =_xlfn.XLOOKUP(Table1[[#This Row],[Ruta]],#REF!,#REF!) -> #REF! | AH17: 0.1851981 | AI17: 0.81464204 | AJ17: 0.0001598641 | AK17: 40686 | AL17: 32196 | AM17: 0.79132871 | AN17: 0.76950938 | AO17: 0 | AP17: 0 | AQ17: 0.79132871 | AR17: 7415024.3 | AS17: 0 | AT17: 0 | AU17: 0 | AV17: 0 | AW17: 490 | AX17: 230.30887 | AY17: 436.55824 | AZ17: 206.24937 | BA17: Sí | BB17: 2333115.2 | BC17: 2333115.2 | BD17: Sí | BE17: 92.468182 | BF17: 48.897321 | BG17: Sí | BH17: 0.79132871 | BI17: 0.79215712 | BJ17: No | BK17: 330.73831 | BL17: 326.54714 | BM17: Sí | BN17: 2 | BO17: Amarillo - Cerca del tope | BP17: No | BQ17: 0 | BR17: 421 | BS17: 33528 | BT17: 10284 | BU17: 3.26021 | BV17: 24.427553 | BW17: 4048 | BX17: 4605 | BY17: 8653 | BZ17: 0.84140412 | CA17: 0.39362116 | CB17: 0.44778296 | CC17: 0 | CD17: 0.14420459 | CE17: 0 | CF17: 0.014391287 | CG17: 0 | CH17: 0 | CI17: 1.4018134 | CJ17: 0.62634216 | CK17: 568 | CL17: 1158.62 | CM17: =CL17-CK17 -> 590.62 | CN17: 7.1 | CO17: 9.45 | CP17: =CO17-CN17 -> 2.35 | CQ17: 1269.84 | CR17: 330.74 | CS17: =CQ17-CR17 -> 939.1 | CT17: No | CU17: 75.16 | CV17: 556 | CW17: 8653 | CX17: =((CW17-CY17)/BT17)*100 -> 78.397316 | CY17: 590.62 | CZ17: =((CW17)/BT17)*100 -> 84.140412 | DA17: =DB17/(CY17+BT17) -> 622.2247 | DB17: 6766457.2 | DC17: =DD17/(CY17+BT17) -> 13.256237 | DD17: 144156.54 | DE17: 8653 | DF17: 78.762 | DG17: 553.1 | DH17: 84.14 | DI17: 975.518 | DJ17: 10571806 | DK17: 20.796 | DL17: 225368.2 | DM17: 8653 | DN17: 78.933 | DO17: 535.6 | DP17: 84.14 | DQ17: 964.235 | DR17: 10432620 | DS17: 20.559 | DT17: 222440.5
A18: Noreste | B18: Monterrey | C18: Planta Guadalupe | D18: 701304 | E18: Noreste|Planta Guadalupe|701304 | F18: Activa | G18: Sí | H18: Sí | I18: 22 | J18: 89454.87 | K18: 33447.393 | L18: 122902.26 | M18: 5361383 | N18: 1275596 | O18: 4085689 | P18: 98 | Q18: 12167.089 | R18: 6394.5727 | S18: 22541.519 | T18: 2275.8097 | U18: =IFERROR(INDEX('Rentabilidad datos'!$N$2:$N$61,MATCH($C18,'Rentabilidad datos'!$C$2:$C$61,0)),"") -> 31211.901 | V18: =IFERROR(INDEX('Rentabilidad datos'!$O$2:$O$61,MATCH($C18,'Rentabilidad datos'!$C$2:$C$61,0)),"") -> 1486.281 | W18: =IFERROR(INDEX('Rentabilidad datos'!$M$2:$M$61,MATCH($C18,'Rentabilidad datos'!$C$2:$C$61,0)),"") -> 3561.4148 | X18: =IFERROR(INDEX('Rentabilidad datos'!$P$2:$P$61,MATCH($C18,'Rentabilidad datos'!$C$2:$C$61,0)),"") -> 0.41732881 | Y18: C2 | Z18: 56.29932 | AA18: 1 | AB18: 0.98568802 | AC18: 0.014311979 | AD18: =_xlfn.XLOOKUP(Table1[[#This Row],[Ruta]],#REF!,#REF!) -> #REF! | AE18: =_xlfn.XLOOKUP(Table1[[#This Row],[Ruta]],#REF!,#REF!) -> #REF! | AF18: =_xlfn.XLOOKUP(Table1[[#This Row],[Ruta]],#REF!,#REF!) -> #REF! | AG18: =_xlfn.XLOOKUP(Table1[[#This Row],[Ruta]],#REF!,#REF!) -> #REF! | AH18: 0.23792294 | AI18: 0.76205878 | AJ18: 1.8278866e-05 | AK18: 24828 | AL18: 15093 | AM18: 0.60790237 | AN18: 0.76950938 | AO18: 4012.379 | AP18: 2006.1895 | AQ18: 0.68870588 | AR18: 5365686 | AS18: 713216.92 | AT18: 0.13292185 | AU18: 501179.46 | AV18: 0.0022799128 | AW18: 147 | AX18: 355.50825 | AY18: 436.55824 | AZ18: 81.049992 | BA18: Sí | BB18: 429803.72 | BC18: 930983.18 | BD18: Sí | BE18: 56.29932 | BF18: 48.897321 | BG18: Sí | BH18: 0.60790237 | BI18: 0.79215712 | BJ18: No | BK18: 278.68994 | BL18: 326.54714 | BM18: No | BN18: 1 | BO18: Verde - Con espacio | BP18: No | BQ18: 3881.8703 | BR18: 438 | BS18: 39340 | BT18: 12028 | BU18: 3.2707017 | BV18: 27.461187 | BW18: 871 | BX18: 6721 | BY18: 7592 | BZ18: 0.63119388 | CA18: 0.072414366 | CB18: 0.55877951 | CC18: 0.35384104 | CD18: 0 | CE18: 0 | CF18: 0.014965081 | CG18: 0 | CH18: 0 | CI18: 2.4911032 | CJ18: 0.73716319 | CK18: 315 | CL18: 857.81 | CM18: =CL18-CK18 -> 542.81 | CN18: 6.28 | CO18: 9.45 | CP18: =CO18-CN18 -> 3.17 | CQ18: 634.92 | CR18: 278.69 | CS18: =CQ18-CR18 -> 356.23 | CT18: No | CU18: 71.8 | CV18: 316 | CW18: 7592 | CX18: =((CW18-CY18)/BT18)*100 -> 58.606501 | CY18: 542.81 | CZ18: =((CW18)/BT18)*100 -> 63.119388 | DA18: =DB18/(CY18+BT18) -> 303.11466 | DB18: 3810396.8 | DC18: =DD18/(CY18+BT18) -> 7.3932253 | DD18: 92938.83 | DE18: 7592 | DF18: 58.838 | DG18: 515 | DH18: 63.119 | DI18: 502.537 | DJ18: 6303323 | DK18: 12.383 | DL18: 155323.3 | DM18: 7592 | DN18: 58.964 | DO18: 499.8 | DP18: 63.119 | DQ18: 493.352 | DR18: 6180615 | DS18: 12.2 | DT18: 152835.9
A19: Noreste | B19: Monterrey | C19: Planta Guadalupe | D19: 701305 | E19: Noreste|Planta Guadalupe|701305 | F19: Activa | G19: Sí | H19: Sí | I19: 22 | J19: 91800.789 | K19: 32526.984 | L19: 124327.77 | M19: 5837867 | N19: 1405782 | O19: 4432020 | P19: 65 | Q19: 13237.005 | R19: 6394.5727 | S19: 22541.519 | T19: 2275.8097 | U19: =IFERROR(INDEX('Rentabilidad datos'!$N$2:$N$61,MATCH($C19,'Rentabilidad datos'!$C$2:$C$61,0)),"") -> 31211.901 | V19: =IFERROR(INDEX('Rentabilidad datos'!$O$2:$O$61,MATCH($C19,'Rentabilidad datos'!$C$2:$C$61,0)),"") -> 1486.281 | W19: =IFERROR(INDEX('Rentabilidad datos'!$M$2:$M$61,MATCH($C19,'Rentabilidad datos'!$C$2:$C$61,0)),"") -> 3561.4148 | X19: =IFERROR(INDEX('Rentabilidad datos'!$P$2:$P$61,MATCH($C19,'Rentabilidad datos'!$C$2:$C$61,0)),"") -> 0.41732881 | Y19: C2 | Z19: 69.360544 | AA19: 1 | AB19: 0.99208324 | AC19: 0.0079167614 | AD19: =_xlfn.XLOOKUP(Table1[[#This Row],[Ruta]],#REF!,#REF!) -> #REF! | AE19: =_xlfn.XLOOKUP(Table1[[#This Row],[Ruta]],#REF!,#REF!) -> #REF! | AF19: =_xlfn.XLOOKUP(Table1[[#This Row],[Ruta]],#REF!,#REF!) -> #REF! | AG19: =_xlfn.XLOOKUP(Table1[[#This Row],[Ruta]],#REF!,#REF!) -> #REF! | AH19: 0.24080405 | AI19: 0.75918482 | AJ19: 1.1134204e-05 | AK19: 30588 | AL19: 19260 | AM19: 0.62965869 | AN19: 0.76950938 | AO19: 4277.753 | AP19: 2138.8765 | AQ19: 0.69958404 | AR19: 5837519.4 | AS19: 648272.75 | AT19: 0.11105278 | AU19: 455543.01 | AV19: 0.0020723083 | AW19: 160 | AX19: 303.09031 | AY19: 436.55824 | AZ19: 133.46793 | BA19: Sí | BB19: 903181.1 | BC19: 1358724.1 | BD19: Sí | BE19: 69.360544 | BF19: 48.897321 | BG19: Sí | BH19: 0.62965869 | BI19: 0.79215712 | BJ19: No | BK19: 281.92239 | BL19: 326.54714 | BM19: No | BN19: 1 | BO19: Verde - Con espacio | BP19: No | BQ19: 0 | BR19: 164 | BS19: 9985 | BT19: 3234 | BU19: 3.0875077 | BV19: 19.719512 | BW19: 3234 | BX19: 0 | BY19: 3234 | BZ19: 1 | CA19: 1 | CB19: 0 | CC19: 0 | CD19: 0 | CE19: 0 | CF19: 0 | CG19: 0 | CH19: 0 | CI19: 0.70105158 | CJ19: 1.5022534 | CK19: 335 | CL19: 519.13 | CM19: =CL19-CK19 -> 184.13 | CN19: 12.17 | CO19: 9.45 | CP19: =CO19-CN19 -> -2.72 | CQ19: 1269.84 | CR19: 281.92 | CS19: =CQ19-CR19 -> 987.92 | CT19: Sí | CU19: 129 | CV19: 362 | CW19: 3234 | CX19: =((CW19-CY19)/BT19)*100 -> 94.306432 | CY19: 184.13 | CZ19: =((CW19)/BT19)*100 -> 100 | DA19: =DB19/(CY19+BT19) -> 678.8711 | DB19: 2320469.7 | DC19: =DD19/(CY19+BT19) -> 16.62227 | DD19: 56817.08 | DE19: 3234 | DF19: 95.94 | DG19: 131.3 | DH19: 100 | DI19: 1502.206 | DJ19: 5055393 | DK19: 33.723 | DL19: 113487.9 | DM19: 3234 | DN19: 96.187 | DO19: 123.3 | DP19: 100 | DQ19: 1490.843 | DR19: 5005229 | DS19: 33.326 | DT19: 111886.5
A20: Noreste | B20: Monterrey | C20: Planta Guadalupe | D20: 701306 | E20: Noreste|Planta Guadalupe|701306 | F20: Activa | G20: Sí | H20: Sí | I20: 22 | J20: 109613.57 | K20: 38136.486 | L20: 147750.05 | M20: 6477694 | N20: 1667637 | O20: 4810057 | P20: 0 | Q20: 14755.564 | R20: 6394.5727 | S20: 22541.519 | T20: 2275.8097 | U20: =IFERROR(INDEX('Rentabilidad datos'!$N$2:$N$61,MATCH($C20,'Rentabilidad datos'!$C$2:$C$61,0)),"") -> 31211.901 | V20: =IFERROR(INDEX('Rentabilidad datos'!$O$2:$O$61,MATCH($C20,'Rentabilidad datos'!$C$2:$C$61,0)),"") -> 1486.281 | W20: =IFERROR(INDEX('Rentabilidad datos'!$M$2:$M$61,MATCH($C20,'Rentabilidad datos'!$C$2:$C$61,0)),"") -> 3561.4148 | X20: =IFERROR(INDEX('Rentabilidad datos'!$P$2:$P$61,MATCH($C20,'Rentabilidad datos'!$C$2:$C$61,0)),"") -> 0.41732881 | Y20: C2 | Z20: 54.061503 | AA20: 1 | AB20: 0.99854315 | AC20: 0.0014568456 | AD20: =_xlfn.XLOOKUP(Table1[[#This Row],[Ruta]],#REF!,#REF!) -> #REF! | AE20: =_xlfn.XLOOKUP(Table1[[#This Row],[Ruta]],#REF!,#REF!) -> #REF! | AF20: =_xlfn.XLOOKUP(Table1[[#This Row],[Ruta]],#REF!,#REF!) -> #REF! | AG20: =_xlfn.XLOOKUP(Table1[[#This Row],[Ruta]],#REF!,#REF!) -> #REF! | AH20: 0.257443 | AI20: 0.742557 | AJ20: 0 | AK20: 23733 | AL20: 13813 | AM20: 0.5820166 | AN20: 0.76950938 | AO20: 4449.7662 | AP20: 2224.8831 | AQ20: 0.67576299 | AR20: 6477692.5 | AS20: 1043372.8 | AT20: 0.16107168 | AU20: 733180.89 | AV20: 0.0033353093 | AW20: 88 | AX20: 468.95623 | AY20: 436.55824 | AZ20: 0 | BA20: No | BB20: 0 | BC20: 733180.89 | BD20: Sí | BE20: 54.061503 | BF20: 48.897321 | BG20: Sí | BH20: 0.5820166 | BI20: 0.79215712 | BJ20: No | BK20: 336.56048 | BL20: 326.54714 | BM20: Sí | BN20: 2 | BO20: Amarillo - Cerca del tope | BP20: No | BQ20: 4216.501 | BR20: 198 | BS20: 14988 | BT20: 4599 | BU20: 3.2589693 | BV20: 23.227273 | BW20: 4599 | BX20: 0 | BY20: 4599 | BZ20: 1 | CA20: 1 | CB20: 0 | CC20: 0 | CD20: 0 | CE20: 0 | CF20: 0 | CG20: 0 | CH20: 0 | CI20: 0.60048038 | CJ20: 0.80064051 | CK20: 244 | CL20: 588.63 | CM20: =CL20-CK20 -> 344.63 | CN20: 6.4 | CO20: 9.45 | CP20: =CO20-CN20 -> 3.05 | CQ20: 1269.84 | CR20: 336.56 | CS20: =CQ20-CR20 -> 933.28 | CT20: No | CU20: 67.72 | CV20: 307 | CW20: 4599 | CX20: =((CW20-CY20)/BT20)*100 -> 92.506414 | CY20: 344.63 | CZ20: =((CW20)/BT20)*100 -> 100 | DA20: =DB20/(CY20+BT20) -> 506.93575 | DB20: 2506102.8 | DC20: =DD20/(CY20+BT20) -> 14.008526 | DD20: 69252.97 | DE20: 4599 | DF20: 92.737 | DG20: 334 | DH20: 100 | DI20: 1058.192 | DJ20: 5220090 | DK20: 28.906 | DL20: 142594.4 | DM20: 4599 | DN20: 92.764 | DO20: 332.8 | DP20: 100 | DQ20: 1056.429 | DR20: 5210059 | DS20: 28.862 | DT20: 142341.5
... A25: Noreste | B25: Monterrey | C25: Planta Guadalupe | D25: 701311 | E25: Noreste|Planta Guadalupe|701311 | F25: Activa | G25: Sí | H25: Sí | I25: 22 | J25: 77165.217 | K25: 44373.546 | L25: 121538.76 | M25: 6950472 | N25: 1176681 | O25: 5773791 | P25: 0 | Q25: 15760.708 | R25: 6394.5727 | S25: 22541.519 | T25: 2275.8097 | U25: =IFERROR(INDEX('Rentabilidad datos'!$N$2:$N$61,MATCH($C25,'Rentabilidad datos'!$C$2:$C$61,0)),"") -> 31211.901 | V25: =IFERROR(INDEX('Rentabilidad datos'!$O$2:$O$61,MATCH($C25,'Rentabilidad datos'!$C$2:$C$61,0)),"") -> 1486.281 | W25: =IFERROR(INDEX('Rentabilidad datos'!$M$2:$M$61,MATCH($C25,'Rentabilidad datos'!$C$2:$C$61,0)),"") -> 3561.4148 | X25: =IFERROR(INDEX('Rentabilidad datos'!$P$2:$P$61,MATCH($C25,'Rentabilidad datos'!$C$2:$C$61,0)),"") -> 0.41732881 | Y25: C2 | Z25: 71.004535 | AA25: 1 | AB25: 0.9974888 | AC25: 0.0025111964 | AD25: =_xlfn.XLOOKUP(Table1[[#This Row],[Ruta]],#REF!,#REF!) -> #REF! | AE25: =_xlfn.XLOOKUP(Table1[[#This Row],[Ruta]],#REF!,#REF!) -> #REF! | AF25: =_xlfn.XLOOKUP(Table1[[#This Row],[Ruta]],#REF!,#REF!) -> #REF! | AG25: =_xlfn.XLOOKUP(Table1[[#This Row],[Ruta]],#REF!,#REF!) -> #REF! | AH25: 0.16929512 | AI25: 0.83070488 | AJ25: 0 | AK25: 31313 | AL25: 23972 | AM25: 0.76556063 | AN25: 0.76950938 | AO25: 123.64735 | AP25: 61.823675 | AQ25: 0.76753501 | AR25: 6950472.3 | AS25: 17925.235 | AT25: 0.0025789953 | AU25: 12596.111 | AV25: 5.7300902e-05 | AW25: 469 | AX25: 289.94128 | AY25: 436.55824 | AZ25: 146.61697 | BA25: Sí | BB25: 1234895.3 | BC25: 1247491.4 | BD25: Sí | BE25: 71.004535 | BF25: 48.897321 | BG25: Sí | BH25: 0.76556063 | BI25: 0.79215712 | BJ25: No | BK25: 275.5981 | BL25: 326.54714 | BM25: No | BN25: 1 | BO25: Verde - Con espacio | BP25: No | BQ25: 0 | BR25: 388 | BS25: 28328 | BT25: 9433 | BU25: 3.0030743 | BV25: 24.311856 | BW25: 1872 | BX25: 4234 | BY25: 6106 | BZ25: 0.64730202 | CA25: 0.19845224 | CB25: 0.44884978 | CC25: 0 | CD25: 0.044100498 | CE25: 0 | CF25: 0.30859748 | CG25: 0 | CH25: 0 | CI25: 1.6591358 | CJ25: 1.0590229 | CK25: 359 | CL25: 638.44 | CM25: =CL25-CK25 -> 279.44 | CN25: 5.62 | CO25: 9.45 | CP25: =CO25-CN25 -> 3.83 | CQ25: 1269.84 | CR25: 275.6 | CS25: =CQ25-CR25 -> 994.24 | CT25: No | CU25: 59.52 | CV25: 433 | CW25: 5654 | CX25: =((CW25-CY25)/BT25)*100 -> 56.976148 | CY25: 279.44 | CZ25: =((CW25)/BT25)*100 -> 59.938514 | DA25: =DB25/(CY25+BT25) -> 275.02458 | DB25: 2671159.7 | DC25: =DD25/(CY25+BT25) -> 6.1511484 | DD25: 59742.66 | DE25: 5654 | DF25: 57.431 | DG25: 236.5 | DH25: 59.939 | DI25: 676.285 | DJ25: 6539336 | DK25: 14.39 | DL25: 139148.2 | DM25: 5654 | DN25: 57.654 | DO25: 215.5 | DP25: 59.939 | DQ25: 661.377 | DR25: 6381322 | DS25: 14.116 | DT25: 136203.4
A26: Noreste | B26: Monterrey | C26: Planta Guadalupe | D26: 701312 | E26: Noreste|Planta Guadalupe|701312 | F26: Activa | G26: Sí | H26: Sí | I26: 22 | J26: 58323.899 | K26: 23824.266 | L26: 82148.165 | M26: 3708488 | N26: 858124 | O26: 2850243 | P26: 121 | Q26: 9409.7782 | R26: 6394.5727 | S26: 22541.519 | T26: 2275.8097 | U26: =IFERROR(INDEX('Rentabilidad datos'!$N$2:$N$61,MATCH($C26,'Rentabilidad datos'!$C$2:$C$61,0)),"") -> 31211.901 | V26: =IFERROR(INDEX('Rentabilidad datos'!$O$2:$O$61,MATCH($C26,'Rentabilidad datos'!$C$2:$C$61,0)),"") -> 1486.281 | W26: =IFERROR(INDEX('Rentabilidad datos'!$M$2:$M$61,MATCH($C26,'Rentabilidad datos'!$C$2:$C$61,0)),"") -> 3561.4148 | X26: =IFERROR(INDEX('Rentabilidad datos'!$P$2:$P$61,MATCH($C26,'Rentabilidad datos'!$C$2:$C$61,0)),"") -> 0.41732881 | Y26: C2 | Z26: 55.694215 | AA26: 1 | AB26: 0.99979695 | AC26: 0.00020304771 | AD26: =_xlfn.XLOOKUP(Table1[[#This Row],[Ruta]],#REF!,#REF!) -> #REF! | AE26: =_xlfn.XLOOKUP(Table1[[#This Row],[Ruta]],#REF!,#REF!) -> #REF! | AF26: =_xlfn.XLOOKUP(Table1[[#This Row],[Ruta]],#REF!,#REF!) -> #REF! | AG26: =_xlfn.XLOOKUP(Table1[[#This Row],[Ruta]],#REF!,#REF!) -> #REF! | AH26: 0.23139457 | AI26: 0.7685728 | AJ26: 3.2627853e-05 | AK26: 13478 | AL26: 16266 | AM26: 0.7544888 | AN26: 0.76950938 | AO26: 202.44748 | AP26: 101.22374 | AQ26: 1.2143659 | AR26: 3707452.6 | AS26: 23071.574 | AT26: 0.006223026 | AU26: 16212.457 | AV26: 7.3752003e-05 | AW26: 463 | AX26: 227.92651 | AY26: 436.55824 | AZ26: 208.63173 | BA26: Sí | BB26: 1192347.3 | BC26: 1208559.7 | BD26: Sí | BE26: 55.694215 | BF26: 48.897321 | BG26: Sí | BH26: 0.7544888 | BI26: 0.79215712 | BJ26: No | BK26: 208.49788 | BL26: 326.54714 | BM26: No | BN26: 1 | BO26: Verde - Con espacio | BP26: No | BQ26: 0 | BR26: #N/A | BS26: #N/A | BT26: #N/A | BU26: #N/A | BV26: #N/A | BW26: #N/A | BX26: #N/A | BY26: #N/A | BZ26: #N/A | CA26: #N/A | CB26: #N/A | CC26: #N/A | CD26: #N/A | CE26: #N/A | CF26: #N/A | CG26: #N/A | CH26: #N/A | CI26: #N/A | CJ26: #N/A | CM26: =CL26-CK26 -> 0 | CP26: =CO26-CN26 -> 0 | CS26: =CQ26-CR26 -> 0 | CX26: =((CW26-CY26)/BT26)*100 -> #N/A | CZ26: =((CW26)/BT26)*100 -> #N/A | DA26: =DB26/(CY26+BT26) -> #N/A | DC26: =DD26/(CY26+BT26) -> #N/A
A27: Noreste | B27: Monterrey | C27: Planta Guadalupe | D27: 701313 | E27: Noreste|Planta Guadalupe|701313 | F27: Activa | G27: Sí | H27: Sí | I27: 22 | J27: 69687.162 | K27: 13658.734 | L27: 83345.896 | M27: 3073739 | N27: 1071382 | O27: 2002357 | P27: 0 | Q27: 7584.5374 | R27: 6394.5727 | S27: 22541.519 | T27: 2275.8097 | U27: =IFERROR(INDEX('Rentabilidad datos'!$N$2:$N$61,MATCH($C27,'Rentabilidad datos'!$C$2:$C$61,0)),"") -> 31211.901 | V27: =IFERROR(INDEX('Rentabilidad datos'!$O$2:$O$61,MATCH($C27,'Rentabilidad datos'!$C$2:$C$61,0)),"") -> 1486.281 | W27: =IFERROR(INDEX('Rentabilidad datos'!$M$2:$M$61,MATCH($C27,'Rentabilidad datos'!$C$2:$C$61,0)),"") -> 3561.4148 | X27: =IFERROR(INDEX('Rentabilidad datos'!$P$2:$P$61,MATCH($C27,'Rentabilidad datos'!$C$2:$C$61,0)),"") -> 0.41732881 | Y27: C2 | Z27: 30.527197 | AA27: 1 | AB27: 0.99994632 | AC27: 5.368055e-05 | AD27: =_xlfn.XLOOKUP(Table1[[#This Row],[Ruta]],#REF!,#REF!) -> #REF! | AE27: =_xlfn.XLOOKUP(Table1[[#This Row],[Ruta]],#REF!,#REF!) -> #REF! | AF27: =_xlfn.XLOOKUP(Table1[[#This Row],[Ruta]],#REF!,#REF!) -> #REF! | AG27: =_xlfn.XLOOKUP(Table1[[#This Row],[Ruta]],#REF!,#REF!) -> #REF! | AH27: 0.34855985 | AI27: 0.65144015 | AJ27: 0 | AK27: 7296 | AL27: 7932 | AM27: 0.81154057 | AN27: 0.76950938 | AO27: 0 | AP27: 0 | AQ27: 1.0871711 | AR27: 3071737.6 | AS27: 0 | AT27: 0 | AU27: 0 | AV27: 0 | AW27: 490 | AX27: 387.25891 | AY27: 436.55824 | AZ27: 49.299337 | BA27: Sí | BB27: 137393.26 | BC27: 137393.26 | BD27: Sí | BE27: 30.527197 | BF27: 48.897321 | BG27: No | BH27: 0.81154057 | BI27: 0.79215712 | BJ27: Sí | BK27: 205.79234 | BL27: 326.54714 | BM27: No | BN27: 1 | BO27: Verde - Con espacio | BP27: No | BQ27: 3735.4002 | BR27: 123 | BS27: 2953 | BT27: 863 | BU27: 3.4217845 | BV27: 7.0162602 | BW27: 498 | BX27: 0 | BY27: 498 | BZ27: 0.57705678 | CA27: 0.57705678 | CB27: 0 | CC27: 0 | CD27: 0 | CE27: 0 | CF27: 0.42294322 | CG27: 0 | CH27: 0 | CI27: 3.0477481 | CJ27: 2.031832 | CK27: 65 | CL27: 182.27 | CM27: =CL27-CK27 -> 117.27 | CN27: 3.36 | CO27: 9.45 | CP27: =CO27-CN27 -> 6.09 | CQ27: 634.92 | CR27: 205.79 | CS27: =CQ27-CR27 -> 429.13 | CT27: No | CU27: 37.5 | CV27: 53 | CW27: 498 | CX27: =((CW27-CY27)/BT27)*100 -> 44.117034 | CY27: 117.27 | CZ27: =((CW27)/BT27)*100 -> 57.705678 | DA27: =DB27/(CY27+BT27) -> 748.09391 | DB27: 733334.02 | DC27: =DD27/(CY27+BT27) -> 20.762892 | DD27: 20353.24 | DE27: 498 | DF27: 47.869 | DG27: 84.9 | DH27: 57.706 | DI27: 1404.572 | DJ27: 1331383 | DK27: 39.412 | DL27: 37358.8 | DM27: 498 | DN27: 49.054 | DO27: 74.7 | DP27: 57.706 | DQ27: 1360.667 | DR27: 1275844 | DS27: 38.224 | DT27: 35841.3
